Workbook

Sheet Recap
C3: No extra activity | D3: Mild additions | E3: Strong additions | F3: Fully evasive
B4: 2018 | C4: ='2018'!A4 -> 88 | D4: ='2018'!B4 -> 38 | E4: ='2018'!C4 -> 43 | F4: ='2018'!D4 -> 33 | G4: =sum(C4:F4) -> 202
B5: 84.1286 | C5: ='2019.05.11'!A4 -> 74 | D5: ='2019.05.11'!B4 -> 30 | E5: ='2019.05.11'!C4 -> 21 | F5: ='2019.05.11'!D4 -> 30 | G5: =sum(C5:F5) -> 155
B6: 84.132975 | C6: ='2019.11.29'!A4 -> 26 | D6: ='2019.11.29'!B4 -> 3 | E6: ='2019.11.29'!C4 -> 24 | F6: ='2019.11.29'!D4 -> 10 | G6: =sum(C6:F6) -> 63
B7: 84.170208 | C7: ='2020.05.06'!A4 -> 12 | D7: ='2020.05.06'!B4 -> 10 | E7: ='2020.05.06'!C4 -> 8 | F7: ='2020.05.06'!D4 -> 8 | G7: =sum(C7:F7) -> 38
B8: 84.174525 | C8: ='2020.11.19'!A4 -> 18 | D8: ='2020.11.19'!B4 -> 9 | E8: ='2020.11.19'!C4 -> 10 | F8: ='2020.11.19'!D4 -> 6 | G8: =sum(C8:F8) -> 43
B9: 84.211285 | C9: ='2021.04.15'!A4 -> 33 | D9: ='2021.04.15'!B4 -> 8 | E9: ='2021.04.15'!C4 -> 15 | F9: ='2021.04.15'!D4 -> 11 | G9: =sum(C9:F9) -> 67
B10: 84.216007 | C10: ='2021.11.03'!A4 -> 49 | D10: ='2021.11.03'!B4 -> 13 | E10: ='2021.11.03'!C4 -> 34 | F10: ='2021.11.03'!D4 -> 8 | G10: =sum(C10:F10) -> 104
B11: 2022 | C11: ='2022'!A4 -> 30 | D11: ='2022'!B4 -> 13 | E11: ='2022'!C4 -> 13 | F11: ='2022'!D4 -> 19 | G11: =sum(C11:F11) -> 75
B12: 2023 | C12: ='2023'!A4 -> 21 | D12: ='2023'!B4 -> 10 | E12: ='2023'!C4 -> 7 | F12: ='2023'!D4 -> 16 | G12: =sum(C12:F12) -> 54
C13: =sum(C4:C12) -> 351 | D13: =sum(D4:D12) -> 134 | E13: =sum(E4:E12) -> 175 | F13: =sum(F4:F12) -> 141 | G13: =sum(C13:F13) -> 801

Sheet 2018
B1: Additional behaviors | E1: Inconclusive | L1: Discarded
B2: =sum(B4:D4) -> 114 | E2: =sum(E4:K4) -> 79 | L2: =sum(L4:N4) -> 25
A3: No extra activity | B3: Mild additions | C3: Strong additions | D3: Fully evasive | E3: Cmd-line arguments | F3: DynamoRIO bugs | G3: External dependencies | H3: PoC evaders | I3: Interactive | J3: Unable to start program | K3: Undetermined evasions | L3: x64 | M3: Themida | N3: .NET/VB
A4: =COUNTA(A5:A92) -> 88 | B4: =COUNTA(B5:B42) -> 38 | C4: =COUNTA(C5:C47) -> 43 | D4: =COUNTA(D5:D37) -> 33 | E4: =COUNTA(E5:E10) -> 6 | F4: =COUNTA(F5:F10) -> 6 | G4: =COUNTA(G5:G19) -> 15 | H4: =COUNTA(H5:H6) -> 2 | I4: =COUNTA(I5:I23) -> 19 | J4: =COUNTA(J5:J16) -> 12 | K4: =COUNTA(K5:K23) -> 19 | L4: =COUNTA(L5:L15) -> 11 | M4: =COUNTA(M5:M13) -> 9 | N4: =COUNTA(N5:N9) -> 5
A5: 6671e5724a53523091bb778c5cf4fd682f57358ca798e18e6f1209d265b06f2b | B5: a2fed68b8423a8ee33a05e6809ba936abc66067426aa04884004c6e61acf9f7c | C5: 9ae26aa69f12107450ff875f32bab7c9eaee830c5381193fb99e8c7a7b81a475 | D5: d8e17c92767c5ddc6da19c47522e5a61f355a90a01892d0c8575b7dd43006902 | E5: 89244ef0e759bce0d4140918866553ecb1f43be8391cc773675dafb311e51c63 | F5: 7c0830550a9b1ed02a20394ca8163526d56f8c162416c2472de5611ff2fcd7c1 | G5: 2b3ed45a72c0e71a2f0ccf9f8307d0a094e79c66cff078c3a7a4e515edd29302 | H5: f29937d78404d05594e444ad22a07cf1eaa09c57140723026cd30af0f43a9cba | I5: 376a6005c1af653f2890ee9c3b67cc95505dd513cfcc3268096d0747f3c99a5c | J5: cc3156338d097d762e7f8cbb23101d636b1727adaceddc947c941b0dbe0c9d6b | K5: 31d23b7f48bf29b1d7c934724c566739f42f80c89df4cc8b06a3af7ef04e144e | L5: 24480b17e8c0c330e6000f039209e05854b8d268efca7999a70d361cdbf6d864 | M5: 28847efcc178f5a853a6b5c7a1fce0bd71755294af926690ef95734699a7690d | N5: 30afd129dc6732fa3e543e9909b0bf4fe87220ac69291f8d9d406d65c91d3f51
A6: 02b1ab870683aa2d96dd88d74c72849c3acd936313d27dad7a7f584ae4ff00dc | B6: e1177f7306cdc7426b37794d7877b600d1d2d8d95a485269a527764ce90c72cd | C6: c59bce3c046f269362629ac44a4078b2511dc05f2cf67e4c2c35da5e052d88ca | D6: 6b0365cf585ab70937ea56e3516c41513c318e478b9ea61d4fbfc689047a6c66 | E6: dd36ab3d753c0708dbacd5eb86d17019a8110b70d3ba388f9135c3827ba6dbbf | F6: cc6006e56f032c8b58ea26844e9d19bb3504cf2359ba1c5d51107a39cfba2815 | G6: ede2a3dc3b6e0166675cf471d9953d587644b2248f11065ad0b88f05d7c9e85d | H6: c135b89d9358e42d6c204120745346cdfc72900bd025208214f1108a9690e13d | I6: 0d67798fe8f4086c22fab8be62a517ee1ec9c2f0c8f5b95365c89aecbbf1f882 | J6: 5ee4efd4261eac13cddc0261285b234db18165d4eac508309a474463c4c3302e | K6: 0bba9d231c5b96afb700d4bba27f8544d1482c9ee7ea414446c322f2d5163f2c | L6: 021b25fbeb0ac5f2d2c2f7d50fe8db9ec5c1a589630035568df07d15c841a25d | M6: bbf524a54c94ab280c6783d18ab5cb8af7d22e160f2337c8bfc4fd770863938a | N6: bbc20a4288adceb037beb1e53dcf500f19d02512a9dbb64bc3d24ff6c8516a4e
A7: 11b8afcce24dd827445ab384d4abda5cd13fa75fcbd8e529c274a88ec7598e57 | B7: 37ffba575c8dab5270a3435aafa3b766a13bfc257587d620e8ee8ae8315ce942 | C7: 952440b5592895e6f775ee700126bfea25321e088923f950e553f0590d616a8b | D7: 5c97882d7b60b90d6f30b8e7fddcc995f3360616087db400dfcc17d8fa2021cf | E7: 35d4d28f21ad33f90596c25b5fc7a3415b8f45f9b032c5e83637c81d615359bf | F7: 68efbe14daec0f1e02b5dfcf1d4a5bee29791b367e258ac93f799da83fb7f129 | G7: 6751cde736ae4c0d3328d532c2a3d60c0ab3c97e31130866efbdeb7cc16a855b | I7: 23c67a5992dd7722391532232c5bac5c1dccb5017a4086e12a6438dce86cb82a | J7: fe4ecfe638c0b3c94d6bda8a0e2c1c03a50d91cad2483e667de1a1f8942394eb | K7: 221e8ab912722c010870ab4dbaaf2f9f472f3c30ba4280a45c9b15dbf0ec984a | L7: ea80ed58cfe0fd6ab9be429d102ea9232a8bfa5abfbdeab8ba67ef480a04e07f | M7: 3dba59bad77eaaf992914e52b2e9d5983c508a57991e3674353e1291774f18e4 | N7: cc3068df3417e53ccb2092a41af3fa6259918b924782f330e578378dffec7e21
A8: 01a35297b3b46759564b04293a2a88862b4889ffaf7b2f72f8a5798d24dad11d | B8: 33c56b8ef471b36847e05018fec37e635876a6a5d9d247d167abf28adc850df0 | C8: 003af1dfc65a3a7d23d4fff95bf6a04511ba2d1ef4672678c0554f74613e80d5 | D8: 0d844f1bf79588bc4a8c46c516fcf7de110b19d55a215f7e3f547d2f755455d9 | E8: 945bc20b8b0c0e6c71d54ad8ec98473e4456ba999e652de149eb701ffdf1b0af | F8: 0be229b01df3cbfad4644c6c2aa459a1446ad16efadcb4f9858089d4952e5202 | G8: 4fbfd4c6daa9f6294f391c7f62869297ce08a69bfa1c06edf95587b9d0f67278 | I8: 47832cde83af5cc0d1b6efdc931f88382ca1123d4f55c52eef0897903f5eff4d | J8: a5b7bb0e895577f55c2a98c992122ef79b9613b80c5171cd0e7d282ec5a971d6 | K8: 1cb1bf783acdb6de99b23862f68968d7d5f0c8000c9783408cb99a38e52740cf | L8: 8ffa3b27a28119d8f93e091504b8ff5554cc80b486180e9594bc00ba9f5cd19f | M8: b4d74fde6118f7328bf6d45c50256108f6cdf294b2736a14d4b62c709f8e7ab2 | N8: b63c8d390918d7a54d2b69a2fd1a6b1187f401c05a1aac5f8bde13e22f57c905
A9: 025e935886f94e167c0cfcbdcfdcf7350c8be93e130aadf5ae1b43a1028c52ef | B9: 352824089171d6ba917e755d2714cb282b04fd7977d5a07718117b425fecb27e | C9: 17171c51ebf56ab9e8ead1e508423fa89770b6549dc7070b8cd9606588ccb4f7 | D9: c6c30c8d36f10a55b7baf82931b211b1ac3a74d644df677cc967267826b91f1f | E9: b9469ef7a22d7d91d6d99280b5d339145abd644e13354f7340f7edf0f20b30e8 | F9: 12cdef3d2e63f6f331604850f273cc3a275454543030c6fc08ef729273cae460 | G9: 4ab08c0acadc19983f45b2ce2243aef960eb155adfadd2a250be2fc1029261b6 | I9: e79ea9e2a2b93f0337c717739a52396dbfafa3a4b394fe559bd45538da749dc6 | J9: 7e5061758acc674323d12083b95d3f3595ad14e94a19ad4bde36155cffe20c9f | K9: 182bef0e23b71da1294f161d64565ed88efb32c3c55b8e44bd1bb652acb678cd | L9: 0f3ec573ca342cfe050e1b26ed006e324458ce2bdbdb17ff9e1862e6224411d6 | M9: f4fece4b50625e5c70dc096b47f0bc58b89154ae1c953582759747fcd4855cdb | N9: 075978f58789b47057755870be8dc37dc4d942ee17ca2cbfed7b2e1fe09a5467
A10: 364ca337b8eaf631fd8718c932f47108f670de26fb9c72b01cb56cc93d9225bb | B10: b5b1972ab47dd761679031a7f1209fe3877b69825e8d92320229f967e071ce31 | C10: 7508cf45c0cc46586005abfcfa89db939a859d97b225c2340463ef29d65bfa8b | D10: f3cf71782257f1edae634541b12889c40f328609671889c9b12047d412a94d2d | E10: dd771c7584f25cec77361093d29a7d5b590cb1235a96514909daed39185c8193 | F10: e3e71f5c5cf94a05b347e9948ef4f0d04d264ff3e25dab43552bc448a97228c8 | G10: 0b5173234808e49e7c526bba567c8e1aec9d5db517cd22c495547567a5db809b | I10: 301520634d20686130e39695f6a5700aa0d437997cde0fc882ab6b1b799d3621 | J10: 5c4d86cf57af42d46dc77b0892401ba11b0d6f700783fb0c00cdd90f347c833c | K10: 8c13f53a70cd0b0b4ac224359d784123cf8fd6865e54289a608a7a57208c927a | L10: 403974a7c89a2f492653677a58aa4245cfb61cdb7e4fad891ee3019c4b046e43 | M10: 2683aa7072bffca2d076c21309da8d50c633674e65eabef0b1d0f067ff705d26
A11: 016c8a86136d084e1bbb80952decc1f271e6868b70814a1696a3c50c49a70423 | B11: 6d67bc5c801301fbe3780bdd042f82aad890f66842ec830cd8433e17bb2dfd28 | C11: 242715b0c8f64ccfd89fdc4ae4cb9780c6d514546949d80caa1e2bff7d041bcc | D11: f42b84af580ec264cb2c7451566772fc8e3581ef7bb9218016b0cfd3c11c5094 | G11: 73bf6b2fda59186797b2c22e7fe5eaafeec5eb7a993380dc3ca59b40ad8f52b7 | I11: 8041554dc7fc66ba196307d2a02affb81755a66dbe1ee97abded1537a7444140 | J11: 8463fad56d370703c95449ae48590956d5274d15dd44e2a3f74354836ff8fbc4 | K11: 34c09a1d52769f0394e4b03df30d2d436331c2887c86cea6e30060a633e76adf | L11: 212844ecf062fee64e092aae638992a3d2e6cdf497ee4db29a9a14553b881556 | M11: 92d352b38941378c51ee03ea8f27bba09fb759a5e935e52f6107772091fa620a
A12: b23cda0d5f191e8bd04f1e1eb0b482dddbe1a80dde65b1e40bb0406690a490c0 | B12: 0103e0c5b7b968340477bd53a898e0e7acd8bd8e152274bbb0d9fedab2ad247f | C12: f51549ff5e2a4f0da9f093b5ca1f33d969a6ef462285d8bfd2e9da6f82b95fc2 | D12: 940d7641213d508b5a1560ea5d37f3dcdae39587de43e33058f11f96ed800a41 | G12: 1ac0f3cfc29a26587f655efef638feb9d1f489648e1401499c9d123d7bf7994f | I12: 856b86cfc1f8317f89d3b4534324fae664fa9d4498e28208dd250a9366b9a828 | J12: 749029fc81d287e23a4b6a077af9dbc427f02b5488770187217c62f5d24ba6cc | K12: 5bbd82003f4b433f5b9f00b74311e7ad24487a9c76f2d6bcc30704448f0c5458 | L12: 9225fe26bdf1ee9220ea69ce420a8380c637aa3b520c8aaaf54f15912dc6a794 | M12: cadbde336e3d57b34ff44eedbeed42868830144adb80eff7c37254c52e301a1e
A13: 11c64deb6c135ee0766af1b03573ff240d4b9d5bc1d40805e8ab1621951e9296 | B13: de4ff8901766e8fc89e8443f8732394618bf925ce29b6a8aafe1d60f496e7f0e | C13: 0b8c9f441b22bb451ea46001086b21f2691763ecb8d261dff993e4cce7bf03e2 | D13: 8e9032036f6ec6aaf833f8a22e11243a40db5f507247e08235e6a7b35e3a8026 | G13: 78a0002bbeb6e29fee8c2b5685596b474b8b67a3ab3bc06f9c5becbdc5f6551d | I13: cefd3991c699a0e61ff0c4aea9eb25d9bc3e2d9fb387d61d93cb7b88b160bbd9 | J13: 27287b011b77c8d7599ddefeead00986c596431820251e48e2fa05e1b1c728a4 | K13: ccb32259d78b65c73700d7c5c0f7eeeed641703b1d873a172645d098265173ae | L13: 7008fe6128bb7fe00735c802ca5668281f45dd23a3c5849f2b1f22d6906c09fc | M13: 7a8ba457b6578e31ab1aacd4253502776a111cf4f26c8c54d680a9f4996cb100
A14: 35f6acb7e9a9ca10e51a90dcf0c4f3269043d60a4f697f9756cd774347f2ff6d | B14: 0db1f2930bb47fc5fb4baf5d026a777171352bc3982d590981563c829559ae5f | C14: 2007392d812a0de6a35ddc7be5c0adcd8df23659719c3af33aba6a12864dc720 | D14: 29b632f6c30d233adffab26fc1fe0df5bb222e6c276521b06b487249a3a51ae9 | G14: 3f96a3dff41ed73471c7c54c32d441a5f8af5f0558e26fd82032d338ff81052e | I14: 154db1649349c16fc01759163c5f8f1a9992d171933d7ebbe50345f5f9f6b049 | J14: 82413e4cbaf2c9f2258884f15f61134b485fa43a9c3f62dc5cd38b6bc15079ce | K14: d02516775f9d4995e731f20291facb9395bb22c54dd447042c9ee1c746287858 | L14: 608cb0015d519e9ee3f4541e8e19182218caed89bf0dc2a07f61e05c71200409
A15: 666bab2f15e190e4e532624a3bd1a5f6deb094749b306eab2cea0d7ebf708f48 | B15: c46a5bf978e152db635b615ec7433f46d98ad0410ad8bc67460c189d8f59e2ee | C15: 1cf67ece170f88a4946a64b667ce505121c5be03c98a8f6e73e89dceb9a8d1ca | D15: 0357373bc8be4ae3be15825e58e02c7ecd19bbc54afb671224e7a29622378fcf | G15: 2df21d581c40aa75b6b28afceb37ed4cfc76fa8885297633b5af1d1fc047204f | I15: c3d70c889d1df0a2a50a980a461a536b9c4848823d177d37f1bfd601a1cccc68 | J15: 3cfb8596e16167700d005309487ec9d884b2a6ab62216ee042f6cec973ce58ec | K15: 5227d61898664adedb50de89a28538881950ec3fa276237d3ffe44db848b95f2 | L15: dd20f9c47d4287894fbcf0b7a322035bf2944c474da29be124905288ca10597f
A16: 20d4891f2cb683940eb254571dd963fa5868c6494ad6422e20e90488dcd754a6 | B16: 1254d6a460c59dc58ab3242c4c14e96b89e069e486ec6a08612e221c29b196a3 | C16: 132945a03da21e74fa1d45ecc5b24b342d5d29fa6f7f697153c696fedbb74f14 | D16: 55c7ac96fb3e79215cdeb405e1b9a5f4d5aebe954ce1affa7a118047260fb9a0 | G16: 36c7719fb231ba57090b2de1c4b0175f57e6d9fef8b4eb3502d97ba25157ed09 | I16: 0b2e82d67ac298dde1c4d8638b1679b9d436116e586125616363c48675252951 | J16: db959526630f85d92b98b3fb2f848509ae9b078980f3c449049ed8ccbf624652 | K16: 58d3df953782ac68bfcb81cefb410b4412211a2be68feba74974d786f6441793
A17: a0a3460d830dd27200ba2da438bda82535d62be4181006cc338ebcba35da1032 | B17: ecb3fab124fb94877cf22e4deb1c9a2948d6cfef256e8309a90cb3260fac1c81 | C17: 64eecd4136821dd583f0d32e10a81af745f16a04140f1d7aa1b8f176ef66d0c8 | D17: 4350cc71d1bd533e8cc38a57d85943a7311679e1d0e549dc17cb5e3b9f49962f | G17: 92067462e8e23fe5366b0e5a1a35cee71f1fbf5084f97df82b90176527272811 | I17: a0b676cc58c3b2b94003a924b9a77c4aeea81f352319350933531105184257d6 | K17: 96deebd87639399243584d0ca1c8ae66f066907733f38773ccb8923e7e1fb758
A18: 6b1d4f7c3365b1c9ffb305174a86b7449dedda795d23ee533d33384f65e51224 | B18: ace360cee6166fe6ebe4fce3665bd53bbd0fc7b1908a85ee1dd8980eb19647cc | C18: 1bca2e01e0eaa21792da11f4f5a3dc24c3333e94de5e9c02f9c4236669fc5359 | D18: a7a7d53e27d457a23433ed92495e4e5e1d37dc0f308d1268a4d80ad3a0a4aa54 | G18: 0fe2ddd6800d81f171cf9df3365b857947cb0293830fa6c404040a716a6db099 | I18: c9b31a2184a6ad836d6cca536f2be8e280991ed6caed742a8d9a99ce300bf31b | K18: dc49c57e8e7481f3ed0f582b42a711cade3e7a8737387bd8e67a368f3b09aaf3
A19: 21da012ff500c30d935522753f6077747662e5dfa3b8f031519f36f364cc13b5 | B19: 0c4da22031d554fc7d96f95d8ae335b76403ee765beaf5b895962c8260457761 | C19: d12c986c285418af59365aaea50834e55ca025534af1d926a55296db917c5185 | D19: 401f1311820e9643f55a2a0de84bd122c7180575b8fde9a32a1977da8922816e | G19: 7b904ca55cc12215ce57f5369f32925f7388b4f1143e57de431c210eac448ee9 | I19: 056da9ddf4979ef3d60baca1173d42641ebd1a6076f8d48c645599cffa9c005c | K19: 29c998d29735d52d0712e31bb4709aa8f3e594a387fdd118e88df2945642c718
A20: 02f1dc72474a4000bf57aa548c0bfe0081e9f4f49f3df05a3db5777e1318cf68 | B20: d4beb1021a1b10d5091e0534a86fa6d897d164c731f812fe7e467d444c713628 | C20: 20ee649edfd9dbb7a59ee3e000e093907fa0615d444dfca8d33e19e01529a107 | D20: cdae1a408cfd2c835f9eeb7981b9e1b8a369ddfaca7252ce7e7a3ac2414e8c13 | I20: b3a53eeee3ccdfdb2b926b4b845f60a18881d3fb91afb4df59fbcf6d41256da5 | K20: 2908a5e54f0005777b2b0b455a23ca3d749e33f7d9db2178f7894184add2c74e
A21: 6011d1cc2b42f42da9e4caa64522f623c304836eca3645c16a09e7a7aceb977c | B21: 4927d21c92a3f090dbcb6da8d62f2c22ba640b06986ad89582b907cb0ba526cc | C21: 698641d1cbd7f3e7f84b3d57631669bfe0ddf8afe8c6d8786832f1820a40ff7a | D21: cf5b9a177d463c7ed892c135df0e54139fa7a789f80beb81b31064f15600eb99 | I21: ed0c7841a84d3d511ecbbc15152ab32dda341ab29bb546f9eb16ea01987b3303 | K21: 77e93c1a003d81102d3c1efb1dbad95a8b3e85f07d6c0c4e9d924b71c123fe55
A22: 60325ce65ecfa48f284742c1f4815fad3182ae8f5293b368d10a028a0565f7e5 | B22: 39c8cc7365471b1680110e78a2b851d107799316fe6c2571781998e43216d45a | C22: 39dfada47c92660ae13c647811c2fd93677bc9daf7c8597bb1f47064b7f80143 | D22: c853bd732c78b5e0a868f534154f12f7571fb7448721bb702bbab8ff7910555c | I22: fa8d2d3952cdf13709ac97a8a24e896ce357c86760d99b8500531aa4acf20059 | K22: 49953d54b0a2db8190fe82f86b5427c5648456d4d3d7fe445ed2f0c75624daf5
A23: 7bf4ae71e08b0dda11a3da3ad2e6e1d7c75ddaafdf311e2c643ef498b78f5927 | B23: 66719d2fa9f9745fba8204e8997ceab8299a6fd092cabacf3ebca270f7ed3089 | C23: cb8f291b17c423ae944b030fc20442d2206b0ade98650799d1514d846528f2b0 | D23: 89abd7b8eb6b0e99b3b4bcc6dcf8619f338b75dbf7f765f5b568794e5de27db5 | I23: f5741acc761b22380367f4c60992512b2599f8b6b37e27b28da7d56b77a5003f | K23: 159fe8c244dee302dd7166a2f8ab52c336a36318210a1d82cb4a80e979cb3099
A24: 060f1e812fb4105b553b28ab4ad0614253f175123f8bd887716b6b8bea2bc993 | B24: 447d2ac6f0d560ccf95c243e3a012689c06c62f1396bcea5d30155b25ce3fc52 | C24: e59e569da2b621188d38108712d9264327dddef30dcaf6866ca34d3f394a13dd | D24: 0f9b0d7b46774804707b76ea739301351d7aeb1d76dc53259a216e375f0902b9
A25: 010f6c2907c32131ed21a16dc0a305b26abad5b7efb1f2c66c8cfd752b024b56 | B25: 9df418c9b62ae059279babe614a6649d7a714ef12c06f11f104f33155d7a2b7d | C25: 74af6aa3d194c6f5fc6e99a374d952d947868753fde3f6438be8c4af55e8e0db | D25: 11c554d3b5833cbf0c128eaacc4a869ffb9d3802e403c90950a2a7549ace327b
A26: 5dc7840a32a5ec8381fc7814900e2655e1c02daeb6f02315855e039df2796ae6 | B26: 2369bafc3e114a5b0a95a1d2fc59025eaac526caf006814335f486dd06b2e5cb | C26: aa7ca0f20aabb6df1ccf95998090708865f376cb2822cb74e861f16d20af6da5 | D26: 50a7a4e556cd166a10a0c400032df84a0ec97c71e347af0ba47928cc3ec82905
A27: 02472e9c47138069fc10ceaeb0afdbdb8fc6a8b3860f84614384a2ff9bdde4f3 | B27: c52ff075c096c7e996b7e826d7f0085360b623f6f2fc8d43147eaabba0d384f1 | C27: d564c0a65a4d39ad078b1b37ebe18bcd3df026ef43928b0920b29a306b5149ec | D27: aa97fa8e07a79d661dce950c625a8172e78cefa62f0f63ea2414f569ac6261a3
A28: 5abf47dde98d61acb985445042aab12f9056d9977b593c03e61a376d15ed6b7a | B28: 0232714c888103e0b81c1d756d68b06f5e458fa48991dd661a6411b771396d55 | C28: e4002201c5ec00703034df99d5c6e46dcea67e67bab0ef68a8873adce866d534 | D28: 4f8986cbdc7be629dea69e81d7cd11c9cec3a259e273af96e88a0a6bf17948d3
A29: 1c2c7ba17e68120d04daf0282f359b9f58f1a548c029d6b61f5ed1d090043e47 | B29: a1f968ce626b02c2e75ff124a19bcc35158f434ca348e7ee40b6d96370540349 | C29: 99def30693f64c4cfcb1b0ffe44f6bc3b458db143765d2e8e68b371365772c93 | D29: c080ef69ca7d4b081948b1c6ca1ad677eae043595de7f998b79edfb371e840fb
A30: 24a6f77c229c27b6fca3f09357f50cf303e8cf898820408afc53ff27a6cb1fa6 | B30: c0e75e713c7fb200c958148a2fc528cff9a1e2da51b77b492d522cbff43ae054 | C30: 13e42bb0ce4303e61fb7503edfc9f637b1edefbc2a176a68ad04279747aa03c8 | D30: 5c2674f2ef789485933305f1b43848638904461b898bf965066bdcf0db336fb8
A31: ff16c9a7d458bc779794130ad183a077accab00738a043e2dd3e2dad2e0f891b | B31: 33c2d715fc21ea16fc437de8819acc89d0fc1073a37b3616a418657980b83d6e | C31: 16ed56a0d1e29dc3b14774595a634d4068a0181b52c40d5e4608f95305bd1906 | D31: 021637d1579a0d10aef459e407ba43a1d5b8a7d00545852e80e08619776b9fa9
A32: 3d6015bbd7dd5391d353d3752dabd0a71a4b2d5763be2fd4c82ca4940c94a6bb | B32: 026515d5a562d8c815b200fd73b08368dffb9c39616f15da812d208b86fea501 | C32: cb86748d725571519856688b2770e0b4306e41e2d4be89d1c5ee717a753b64a1 | D32: efdf0069d8faedae2200c7fac19749c128bd251c76173286b52caba439e742f1
A33: 04fcee00e429c813dbd415df30ff19ff52f19075110906791d0c6d8444f5d7f7 | B33: 5faaf67e7abc5d78fe84f05680e9c18abc71049374e1ad1dda871bacdb0909b4 | C33: 0c6689d673d3534301cca223f9128a49765b27089d1538e67040de293b008e94 | D33: fc5612a65bbf221aea5799f6695844b9b0f7aa62bbc41aa99d37e93895d24d4c
A34: fc1d8fb3c385fd2b8d8b346ec26fcbc623bf1e305d8960f210845995ac687b11 | B34: 2373521f7afe1572a922b0ccec77418edbd84211773572d8992a6182e57864d8 | C34: c5276b6cb9e193066377557ad695472e6bd7e2123e11dc960b50a546a18acba1 | D34: 10d250f3b86ec55686382a4bfa9c82a6b63293480b5ac298d372f85c9ac37d84
A35: 38bbe391e5fa243be1b4b6cdb7b24633fa763e7b918acac30f8b9aca97d31735 | B35: d82ab1d6ff438ca033de627787fe59b21aa68812f59a02e20195cf5165a1267f | C35: 6eb059bf94f43db0be05c0b5855783410bb46d588970d84a10fa6ff9454dc45a | D35: 2076e94adc02116bf802fb0ef9d40e40b6fedb62bfdbec3b022d5e16fda3d1df
... A37: 0719fa4aaebd161445402551b289001d97e5869bb9584b3135365fdfbcae1a18 | B37: fb6306efe5ea4c4d4d72a9c1f3dcfadc696e2eeb282c6f7b57f9be05eb87fd24 | C37: 25badc8e691fda19bd30bea841262627a4194be3b8d0d8aa5f1fb2cad8004c92 | D37: f2979faa9e6f3029c57abad73794a0331315fbd7157401335450787b3f3ec5d2
A38: 02414cc08002f83ca790c30ddacf024533ec00dbf689412777f1f3675874e764 | B38: 3977e3b6dd94db9e29808fed212dc4f1c3355bbee03195dd6fd6be2b92353d17 | C38: db3e1ba09803c97c02e55f0a0e309325e3d5fed49c204dc6556d49eed5ed80bf
A39: 00c6c98d7b379cf4d0bf000ac18087b937f6ab8f12ef1e123d160f7d7f62c21e | B39: 740a634a99c5528caa092b0c0fee484e86e18a605882e0d800a2e8106e70d19b | C39: be1275a26fe38ec31d50dbb93b8944eadac8d808f1fb3611a8d3b2be8fcf4aa5
A40: 3d2d1d26cf24c2fcf6a54285da8f6807bddf4381d8e5a01b09a0fa7e360a05c4 | B40: 9905cd90f65b8f5fdccb17b525f1c62155af7ae2f22e1f2db5b2e9f4b602ac86 | C40: 6750d857d1ff63e4aed7bd1e09f2e9e59a25b6c934c740a500958908bb93bbe5
A41: 0d7f03308652455545db882d7c4d1e9f66064cd3161ff66b08a08ef3bf82e30c | B41: 010e3af4cebe5d9659fa5c9d8d0dffbc190ae7de56f2f9f78244fa473640af1d | C41: c5757be5fd538257db7c68d16904433bab8248d134236c804ba7c69cf4788c3a
...

Sheet 2019.05.11
B1: Additional behaviors | E1: Inconclusive | L1: Discarded
B2: =sum(B4:D4) -> 81 | E2: =sum(E4:K4) -> 65 | L2: =sum(L4:N4) -> 16
A3: No extra activity | B3: Mild additions | C3: Strong additions | D3: Fully evasive | E3: Cmd-line arguments | F3: DynamoRIO bugs | G3: External dependencies | H3: PoC evaders | I3: Interactive | J3: Unable to start program | K3: Undetermined evasions | L3: x64 | M3: Themida | N3: .NET/VB
A4: =COUNTA(A5:A78) -> 74 | B4: =COUNTA(B5:B34) -> 30 | C4: =COUNTA(C5:C25) -> 21 | D4: =COUNTA(D5:D34) -> 30 | E4: =COUNTA(E5) -> 1 | F4: =COUNTA(F5:F6) -> 2 | G4: =COUNTA(G5:G20) -> 16 | H4: =COUNTA(H5) -> 0 | I4: =COUNTA(I5:I18) -> 14 | J4: =COUNTA(J5:J19) -> 15 | K4: =COUNTA(K5:K21) -> 17 | L4: =COUNTA(L5:L8) -> 4 | M4: =COUNTA(M5:M13) -> 9 | N4: =COUNTA(N5:N7) -> 3
A5: 1fe8540e67e48ea2a9684622071ebf5b4c2e7f85c302a4c291630ee95962c1f4 | B5: 139f95e5b407d255eec98fc8a51f51351cb1abd4ec041a2bfd86511a8f825d72 | C5: 08e6ef369c29700bc029841c9cb0ba4b68936f93ef0ded9c99cfc283bfaddbc7 | D5: 3352d58cf5fc633b53d1533f1eac4e43e5d30b6092b9e3bb6fd86538ef406a54 | E5: 0f035891bee9cb26ba6380921d267785eda148129fedc973452941c956ce7458 | F5: 1d4f063d5fefb843da0853ca303be9c5495461b4917b9495d56c19fba949d0cf | G5: af251831ea2b9acdc7e1a7ce5f1abe1341332fa01b0d75516f39dfae62172ef0 | I5: 226c49916f33470e7b2f1fcfebeca36464caade818e92b83eacddb65b72043ec | J5: 3b425f447bc4ce9747e3ed0d0727920e4a02a998bc2f92b19f27c3e2e6d46dad | K5: 027bf17a7ad08037899e5921cb5acc125156f6e5b65bbab8ad05465eb63a00ee | L5: 7d208e35b7b23c4765fd214d94e2c4fd687de012a329c212aa482f5a8e24dd31 | M5: a12c18dac158ce617a35fe9e91a97850f53d05b71852d2c3e0d0fcf87b67049c | N5: f6932b07de0414d591c0f5463a5e839664919cdeed2f9428a8aea7a0cc641c1a
A6: e05a8f1f34a31088792cae3931a54410d6ae36863ebae5b3b47fcf465111782a | B6: 3ef7b499f350641084311b79952b3973a805689cbc5eeb025cea97c82d773bb9 | C6: 26f491c762101cff43f9bc42285614a6fadf4e7c7cfa859551047198b85af5c8 | D6: 5f6eb83935da7c37d44f02145e77877ca0b251f515bae957b8e62ddbc04a4457 | F6: ac4c2b92578fdef7038750249033b4aa1af370f2cefdd27afd931e1604c7b851 | G6: 490e0c75fffc40f73f13e8b6467bd65c509574515f681836192b45e039f231e6 | I6: c41b54d8b036946bc2597ba8f94c772e71fdc5f9c00213a2a8296eb62779ff23 | J6: 4aa3b9ccad6d3891a1521d7e67ff4f34fa64e3bae3aad3c21cd2c1937994639d | K6: d54d8979ba25e1ed52a49f7643b98c32f86db3b35316ef668276a937bdbf0e12 | L6: eaaf5fc6ee414873f6320ac8984ebc3100b2a3cc23f7bb28312f04f90718308d | M6: 67e3bebbe4f6905e93575ce731d3f54bcfcd04e386d059a9ca5d7a45d07c6da4 | N6: c6c769b293650309036879b8f46173e1c5647cfca39907217f16bf664def78cf
A7: 41662d7c2290c1e6d133edc557e1047d673951b08541b14ba28d68678edb158f | B7: 04b79e57210faf671609ecdc425979ff4444a1822a448b67c4be02ce9bff6546 | C7: 377b23171bd816b413581395bbb69f97728e8eccfb56502a22eba0e1c283c2c5 | D7: 60c82a9266b27982fd63af56b3b92033bdc9c900461e78c6fad05ae538fab448 | G7: b94b7f53138ac45ec72d82c8a2523e84d28efb4e65104f3f4dd65224116f0453 | I7: 39c90be6985479e3e201a1ffd6e1f35373adee2439eb9ddd12027027aa5c2089 | J7: 204349103640bf954efb0fdbe2a36f14e20eab04006ac98f8284b2a49034a772 | K7: 2e3037a6a172d984402d9814e0fc01415e712016a7b19a73beadbc625de36492 | L7: c02c1692c71f107c385618f9127566957f355e57981b7c9bf9d29551a3e27b02 | M7: b5bd8d5b7c5a5895e639808deda588b0761f8a0bd471e0ded4f94982943ae986 | N7: 76f40fcde1390c58e8c7f4761d999b75601798a83ca7e114c62a6fc419edc6f2
A8: 095a1d0bdfb2110f389f27f1cffd178ee2dae8b3d72a810b1b2ce9c796a41af3 | B8: 749b3bcb5fda52b2863fb3a0e4cc934ff01ad7a26b9dd71be891df368bd1c759 | C8: 06a830eb528e690ff46abf839552735189692b96617a512b7eca70c4d1274287 | D8: 79a07ef9978561a4403c0c7de656fa4276b9b51261ed68b063bee33e9617a7cc | G8: c79cfa8201e239714c60f0a5c1b2673faa981e1a51752c4af29374871e9914f9 | I8: 154d189973d80b5637cc45731fda56ae864891df7ada5a7fba52a364343f4190 | J8: 1d815aae13054c9d530dcff6288dfb65c9b521416f3dc8080e40738925f59517 | K8: 341af0cc41e5bb706c4e7962d64ca90154bd7242ec8fd17a49f91b5f7302eb63 | L8: 2f49f678bf45909ffa96cfd896a4ae7d3e9f506e830fa857b39d7ac7c8fc6f40 | M8: aa825e47c48a26fb9b67dd213049e1901b5a993daf5eaf1366b3943c0d38d4a0
A9: 346e302cf0e78ab07dcaa4eb7bb313f936ea9e71ab3ecf3f27463dec7f12b035 | B9: 21fb38391e22b675e21dae6bbd3188913f39707343bde002e59115fe945f763b | C9: b6221d18c2a69649ea3efa2e26f873bbbdc4e013a3d1e2dcf9778b86b097fa3b | D9: e21915a6bd65f346951930f5d5ef4eef8967f9b2a4c68663124233a8e6d7de27 | G9: c4cae4cdbbf7a2482f5bab93e0944aede013b267d6e0b66b0d3d9069307b6c03 | I9: b781a0ad834f27eba054c53052c053bc8b21521e8383dcb6045fc30995a1beb8 | J9: a0cc09131646e4f931a48323dc59b98e7ada2f3a9e94e261065e5f3ca74d5cd6 | K9: 7eff76e2ea628bb5c05f33575cce79ec2ac21be9e311f2076d620882ea292475 | M9: 1f0a10d0f56ef5bd639c9df52be6e45e025556079e7b1eda14db8c1d7c659e5a
A10: f714110ba8557b8567088b80357678277cba736a2a372a0b81331496c2867d49 | B10: 3631a17bdf077bd0583e5c0ee2bb4ee7b9762226556450c65c5a71acefac6bc8 | C10: 0da4d94ecee6743bd7d25c986441edb7d638f24d7969210f07d39057e0be682c | D10: eba896af2ead7e0e3030244f388f5fcd4aab1c1d9f30cbf1506d2e4aeb1ce582 | G10: 36eefe0d2ca7f2dffcbca205f6ebef1c8c306cfc264ffa06425f857ee1e084c5 | I10: 0e210a176f69720c84b10ff8b950ac580ca8fc0b4782be8791ef9eaecac532de | J10: 15e2092a98ca8ba3291acbfa764a9821371e4e3ffa8241b82da225b747fb7f1e | K10: e4170178c833ee8bfc309666943dedb0baa05b947b52a63f1ffe91d4f328b421 | M10: 02421d77a56fc076c6d2ad9fa0be137daae56154706ab3e0030d7a92073d15c5
A11: 2849daf603b2f7b6036d87eca19e736b74b6186e691d487f4e03ca002487aa40 | B11: 0117c5dbb594e2321813c03178f3fc9c43f7a08870453bc6a83058b266ef30fd | C11: 4930bcdacba493955d0c53176a5434ad7269ed82d156160c73039ddee90b553f | D11: d2a6b7e5b06ae0adcd241b52900e3941d0e4f09e1521a0c46ad5b8b0ad454fb5 | G11: 306ed351e4e68948960e048ddf76584c68ee0299123748a6ab07f279bcdd7127 | I11: 3343d06244d52e7a875684b00e8db081b28129bb475844f52c4adba7ec4acf2a | J11: 2e59b2c583685ea874b84874b1f6515d73d7c5f0766b4aa0693187d5c2d244ad | K11: 4dcb4517aa28b64e241cab3575336d341243179c57f566abb0fc0ffdcad66297 | M11: 78f3f3d1d53a60baf7231a86c8bdc8bed17227f6c6147e866229d46a074407bf
A12: 8fbdf82065e62dbeefa1c481450b0a7c3f51eb8dd10acada9e77b06f6156e557 | B12: af140ca3ebce1acec6985548832ea068b70b2667031309d467a100b64bd7b579 | C12: 6749652720da291a688b490ff28005d44c40e6f77c3ccd7f39ea932d98a13d7a | D12: d5a87500e0b494a34afaea09793fda884305fae08846c48e0fb1dcd3dbb437b3 | G12: b2481aeff474bd2425c20a9b9259f057c840eb7fb623242e64839af51884f3bb | I12: 0fb2ff9e461feff1ddfd6664d5264d4ce9ff255b32294e8261d7483c13dee54a | J12: 350275f80a4a3407ad23ee712c4d901a6a12bdb3ba801bdc7efdb63545094025 | K12: 9549d82f45bde74401f5ed49345c0e4a7d21c02daa8eaab08d0018d33eced3d4 | M12: 34938c80b2d86a50c85ffca92dc0c3762b9c5f5fdf1c2b70e3c2b7a1a2a1876a
A13: 092826dd362d4d7264a34d1cd0b1d3d675fb544c8f2524df46c53955278588fc | B13: e1177f7306cdc7426b37794d7877b600d1d2d8d95a485269a527764ce90c72cd | C13: affad84413bc39f7528a6e9a3f8031cceb01005328807c60fba03c9284ab6eee | D13: 50596c0625512b217e341d3ce8bea0864e26a347dead197c170e21793fafd066 | G13: aebcb7206cd2c52731095897a9659d1a2aeed7394b06dcdab959944a82800db5 | I13: 0bcfd6b5440dc9e08c5d143c480d09b36fb19b376d7aa1d8d247d3af1ac0baea | J13: 48c21ee6bd999e4585028744babc114851d55f4d8dc0e42f9cc74532272d7ee9 | K13: 5ef2b5cd17ce65bfd8bacb636ea3800ae17d0bbbd9c9d0084ea9417ab117d53a | M13: f4d7c74899c7f3193d949aa1fd9acbedc57568c061566f51045a5a7192a475d3
A14: 0f01e1755973e953a153b72eaa256b2015983d5ee25e42d6bb84d982510b3545 | B14: 0f3848ec7babdaccab27e88d8adb0617cdea29cea91a0130d723f4a9ed43ea3e | C14: cecac26ff22ce75b5550084c6ef4194b5508c8b7b971371123dbc5e86da3bd92 | D14: 2345d0a949684e12d7bcdb9f6928dda0a3e68622851783adfbde0aa834fb0330 | G14: d54e64d70b9239272b9604f9d16c18680541dddbb897ab36a40ed13aa6605039 | I14: 0314030ae609bee780524a416138c0b59d37bea24cbb45f70f7088f898a81f11 | J14: d2e0f9d029d7f1460e892d0c6f10479f7004cec7fad99d8ca99be42e9907cf42 | K14: 6f217e8390afb3cb641599ea0e5165c0e6b503b0340ece1a00de89d93fcd6500
A15: 8664c1010931e8ab4deb08a07233cb618e3c3f4eaec2d87e1abaaa03d6c908a1 | B15: 03583da0ae079ae9cf3cb09280e71033325a61875ff25c8dd1082f167327d6c8 | C15: 0e0d67c8f4801bef0dd89bdf70eb47eb815b01f2ae9b34215188cf92438453d2 | D15: d9f3e87f291374e3b474654ba80dad527b10b42c6c93dd89e1716ed9c77a9b81 | G15: 5bef34f670b9469a948f6799990e90c130c83f9caa02955cd9d5d3d2cb466ca2 | I15: 646f84f406e6c749178b45b29c91e63c1add21cd0f8512130e53e5a8d85bc229 | J15: 404ba4dbb66aecf3d4fac5eb4c68ea25650c96487aecaa262973bd21c4eba4b3 | K15: e5ca003c03fb2b57bc9456d39607626d0fb397859b258bf8584b5e4c347d2ad4
A16: 099c70ba95facb19d700c08c9c0e7cb43e7a9f830afda08f808b5afa863b0427 | B16: 20edbe572e6610f147f784d0f6e6e196fd42cc2ac00b4f66b44faa707d852762 | C16: 57d440c8cb5f7233a149d35c10fe9b4f3cf81456fce4d32309d725c933039a1e | D16: 4fa9e96ec9ec467b1c026f793dd7881b1c0805735fa5d1f1cebfd914fa34a51b | G16: ce8b1d96b605b55eb173bffdf6fcd2b20c887d81500de4d14b9d830db8bd6cc0 | I16: 9df76d338b6e7472e6f5fb0437097b85407901ca4b0c2cceb1b0982ca66b9029 | J16: bfd3db72d60f90685ba241b457b0944c0bea995a89b15d42511ce505aeeaf641 | K16: 7ab7c5859be3464bfdfd33c446008c422b545106eda256d679bcfde1d523f22f
A17: 3bef791ac185be68d32b4fe45966a2c198e2408c594720154145b417dbe13ec3 | B17: 12fb6b7c367122d6dc79d9332e6b9bc93b9a7556da368008d856a19e4df14f0d | C17: 547bf0876cdbdbdf71ebcf980f443b768fd10572c153a4ee4c4ca320783c718f | D17: 0aac654bbbc74f1b65d7aa9b15760209cabf08b4370b81eab536b4682a9d3f72 | G17: 85974f4e1723d8206504aa53f653dc25494febf8a604231befa8890f5b1076f6 | I17: aafec4733fa28295f631c2ee91424cb3ec500ceab14463c02007ce56ece30d5e | J17: 8de4d204b5ff397d3e808fa60570b850c25b49db9e8f4b07a73809ef0be16dff | K17: 7a52003a0dc3793eff37d045ae2520949aa528d0ca43ac0666ca2af04ee175bf
A18: 39fda9a249286581b13dc1f89228bca1656adeb4e564e0b18f1848082c97acde | B18: 1e08f5649094673504f162459079b70926e4c01c900a5cd41c8ee8c302cf6d7d | C18: 1fbc703275e2f6e0aa03ad805ee0fa8b680768b1cf1d8377abaa8d819be39fed | D18: e11f136e23410fe86e8cebc44175b31908b49d2b03f5184c51283dc1b7d46279 | G18: 5175d9a05ecfd968018c603298a22cc4197f640ba49f6a0ee41db129d3cc24c7 | I18: 739504704c5bf9162d0e83bc0fa33eba56793ace7e8dd610dbc4fd7515fe4196 | J18: e71c0b7571f9872d76983e44760a632fede1bbb39cc28d73120ca3273737bf20 | K18: 40b899898603cda1cf7c4d553c046096269086290fdaa11c7518f02f0787541f
A19: 0c88faaf0931aa429763708fdc3bdd48b677eab1f8314bb8e3b0284d657df593 | B19: 03a6e409be772ac3a65af881ed0b8b55480e8ae6a63b756d7895babba6604a3a | C19: 12c376e26b18d2bd4c348628b134132d9f27d175e3ece7cede959078b5b95046 | D19: 75897455cab694f27ef92827786b23667002636db409c84232bf64e4fead3479 | G19: 753fd102cdd6d6db34e0344b282057718f9cee49c86a937de0e6d8b3e11b4ce0 | J19: 7d2fcae787a6adb6c930b91c53a56c994065789307463561b014ae909a8eca25 | K19: 5b7646d79bfa28b7a9a2822f072c9cf68d90151c76aa244e053ccb198bc0b87d
A20: 2996f383acd643cb98fbbf792be568a2adf7e16051c198e530fbba27a741395e | B20: 579ea01475199be49b0d8cc745f8da19a509adb3978d0d30e78a63a02ff1de89 | C20: 59cc3cf96a6ead5357b52945da399d21fc5eb52bde2701bfa05f82ff0b3aaefa | D20: e311174fd1be580a07220841235ff0fe747ae99d3f948541e836aed934c1064e | G20: ae98c521a4ab0b60be0dac447b828f9fd3fea41d1d929a0ef43e976daa661189 | K20: 5eff64c87d6dec16721c3e3f0cf86bcb79f548f915234dbdc7eadc7e0e740a25
A21: a33c610e5f386ac7b6bf59a3b8c0c31969aeacebe24703b7e3b32342b23a8d80 | B21: 121e9607f3aede50ae339676465f8754763f11094785a5eb7715bf712b5a3c52 | C21: 4815bf095eefbf32be9932a68cd5433a3aef22095d2d6efb425aaee9a20bf507 | D21: bb37698253ee83d6e0d88995e573a81a488b12901d33b24e2a59a54296dcac55 | K21: 86a1ed9a94a0476be034b08f587440fceb1cf071b0e6a15c494bc18cd7e7a886
A22: 537c7d9fa508c60d3ea2975d21755ea7c0569449f26a6f7c72b1cdc32c4a89e3 | B22: 03cb3d7b01f2956efa5806802daba395d41be70f6ee3fec712f5122d5cfad1cf | C22: 23b24a0f95d6e25c44f7238ee85712189740c90919c3988e4b0f34cb7de2b3f0 | D22: e4f152f52599342ece9fdb0933e192e68e36e2b2a1ec1f54e8fc24aa44b8226c
A23: 86f3018bc7d407edd3caf4a5049163baee3af9999fa2ba286ed3d1b5522d692b | B23: 30c0e239568f72da66b0cbd9c4f0a6569663290c4ac95f9ae299b9e60332ff89 | C23: 03ef9b1df282df35f1b513280e8a04c93f8228ad14f54c7333455121b2a382ff | D23: 4680b729788986872608aa10ba00f75bcee18ba81cbf6c79845652014bc8383a
A24: 01ea4a902cd745ed2abe1e1803516268dad8ee1deeeef750db2320dbc0108a31 | B24: 67eb3106eac7501525d5dc5b8712494220fa7abee9db6de66a77ccfc432bff71 | C24: d12ffa8f2fd4932177158f90c3a5c79e86c48465a51bedbe940722ddff802811 | D24: 27981cc903d5f572427906e4a342ae8636e2e928915370e989d3556084425863
A25: 3df35af1c5a88d2526f40fbef09e13d42a2bee23cbc996e6b5b927705eba84ab | B25: 04fa0ab1153e602fe14280190ce4f14ce2c333b92b499000b99de3a691578da5 | C25: d4ac7842b4c77470bc97223a1c146f518b74bd1500e8d107cba5e04023b77d57 | D25: 8836171483fcb12d6fb08661afa951eaf97d189807db2f3ff1013cf4f1e93039
A26: 1b056627f60d0746c80a13068683aadefea6909b2114ffb664cc09d8a9101d5f | B26: f820b283321c92b2e4719f299f7f82f50b8171ba305dc04f75687e4754e1f816 | D26: 43b1415d115728d1c76e75e1d9d81d05a1f4c4b2fe9ca5caa34141b8f8163a68
A27: 14bb0cf4cc8d3e98fee5083b044343c31ae1688b2b013d7a48a9f8aa01272583 | B27: 12f163c70186568ecfe37e2a2352fe86782c1ae4bf60c798ad717a950991b6d5 | D27: 081a04c3abb6dcbcfe10dcbd32b4ee7d3a5f2377a41278d6377f4c5ef55e9dae
A28: 469a449e374c467b9dc7f7415980b13af1783c0d3e81d7021241b0a394a85e69 | B28: 85a6d607299659a07ce9e1f3f56ceec858898ec9670e620eba7b7968ba443fd7 | D28: d300da18fc09da4d8d83ed890fa41bf029c2ef3699f29fb0ec18e426c57056cd
A29: 103996d7cde76f8b36d4d3bbbc1a121932bd4a935dfca90294535fef079fa436 | B29: c83c787f0ab500ce216c6824dfab9d55581df12e227a2069168b79923a31193f | D29: a6bac2582929d42f831ba13cadf8fd8b737bd1243c29afde7ef5f9fcf59747aa
A30: 4c34d7c443e192a3a7bcba1081d62674164939d62346d32f2c37a244cbe76ed4 | B30: c4db2c8f5fdf7fa912553349ce84d67b7abd92ab90afdeb57dd566e9c7c4926a | D30: 303ea68828e74d69f38af796e7f66a3fa35e85582d283f3104b8497654650ac6
A31: 21c4232dd744e6a5733d5402c147541dc0388206e532969d628d4f583d3e1b92 | B31: 187f645bffaa807d3e034f46408255e896a660e2e5275286e744a13cc1624f29 | D31: 5970980d9e53467f1fe1997528e17bf2412ee6ddce40d79c58ead2a80ab36716
A32: 5c1ce9e2711bef169a6ba9a286b4e1f315c859597e550789584974519d2b9491 | B32: 102b468f45c425495b0ce4cfbfe0dfefa160b9d46696400e2f183e57d357ad75 | D32: 33bcaa4f4a0747236a4d7e48e78752f2c49c052477c472011b662d6d00a4ba03
A33: 1ba5782a8a48a48aefa2ec6efcb3d5e5ecafc3a1aaefd1fcb7eadb5df5900fe8 | B33: 6647ebcef93251330c94bd7affbbe4c3ec3331706ab593d665cff60c81c0aeb6 | D33: 284f2d86b21d3c646a96b6f41c8c7537f4048b11c59f2c0c1691e1cdac670572
A34: 25ce8610b85d0615030e7de52c915fe7c091f2d6bd44fba3211b4ec80025050d | B34: 0c91eea615eaa94b6056f82e81e059d3cd3a6a58643ad60c2db8b3384e89e158 | D34: 068e7f0bf9ba89cf4e3df6d817ff8b9233432ea05f9b9cef5cbcaef17f3defe0
A35: 82c911654f0ee48371791f470c0998e9a82e8c09df8dcb8a1257b795922a4b68
A36: 5a74ab9975a4795f083115173f129dc8898a86df080690589e378ee8416cee85
A37: 0183391906812fcdbdba93fffeeef5f7730842f1387cf45f16879a672a522310
A38: 1d999f4a5f06bb47961f88c87e1dddba8d7e26d5a79e3960116b8b87c73508d8
A39: 738b835a095cf68bb42d3e7d2d30ceef7ea2de17234b84614c4cd6a1d5762dd2
A40: 59733101ba85d2904a35a467ed29205b61bedb1efc4c95ede070a8e50a9610a7
...

Sheet 2019.11.29
B1: Additional behaviors | E1: Inconclusive | L1: Discarded
B2: =sum(B4:D4) -> 37 | E2: =sum(E4:K4) -> 12 | L2: =sum(L4:N4) -> 5
A3: No extra activity | B3: Mild additions | C3: Strong additions | D3: Fully evasive | E3: Cmd-line arguments | F3: DynamoRIO bugs | G3: External dependencies | H3: PoC evaders | I3: Interactive | J3: Unable to start program | K3: Undetermined evasions | L3: x64 | M3: Themida | N3: .NET/VB
A4: =COUNTA(A5:A30) -> 26 | B4: =COUNTA(B5:B7) -> 3 | C4: =COUNTA(C5:C28) -> 24 | D4: =COUNTA(D5:D14) -> 10 | E4: =COUNTA(E5) -> 1 | F4: =COUNTA(F5:F6) -> 0 | G4: =COUNTA(G5:G20) -> 0 | H4: =COUNTA(H5) -> 0 | I4: =COUNTA(I5) -> 1 | J4: =COUNTA(J5:J10) -> 6 | K4: =COUNTA(K5:K8) -> 4 | L4: =COUNTA(L5:L8) -> 4 | M4: =COUNTA(M5) -> 1 | N4: =COUNTA(N5) -> 0
A5: 4ca3ed5d3f3aea0bd11672799aafa03059407cf6452b866aca5e585b8a8efe0e | B5: 31e6d44b6784a14b0a6576756e0ad407af78dd07684ba76d8a00235a4efd6cdc | C5: 128be18f47b767904ac41ded425254db336b269cd59fddd454f7eebdc6e9bc86 | D5: 0c29d9ca937a9ed8961ce05b676030ff722caf5a20257940f31a48b893e2d989 | E5: 22aabdf54161b8dc3b37fb6f168f747b1ffc3afeccbf28b5421b492bef2e243c | I5: 17555e90132051b06e5c8932bb77ec0ba5d1e7b34c94f7ae4dc491e1b68b4707 | J5: 59b853e3f4ce4cbcc35bacedc3bb9db647f265c1b4192ff80d8d23415266c2c2 | K5: 0d18cb78787714d2e3f6914dd1e587eb570ede8f761115a74e4aa261fae8725b | L5: bb2481ac09d462d8316a7f170a13d232f7cebfbc4c7194855ad3342b65c92857 | M5: 35690cc3171a94d847bb67612ac03dbab303ad1f482b94179cb501130cbc3587
A6: 0186816c48f06a87b15ab657303f03128f21ecbcd424dc3e4fdebd8298e3be99 | B6: 3fc85ce2f65a0482daa43a3b586732d40be2ab1cebb8783a22a6a9b7e20d0587 | C6: 1d5b160ebf59e2c47ead951afc7afb2cd3cf40b182297371545d397780721ec1 | D6: 0f6094d11540d02405591452d2278a34dc84cdecf0e5ac3bb95abc3dc9449438 | J6: 68af9bc65bb8837253fdc18b5cfb196811272361a951c6bb76b144a3dc85bd06 | K6: 15f3ef8be14afed447a132e3efd075d5b238eeb3297dbc5e7c48731982c935ce | L6: 6e03a0e130521362aa9b43d188287e9bf701653bb8a3ed3ec86394baa4fc9acb
A7: 054072812e4d65421fee8252397ba0d31e056ead17ea9e7153944ec26cbe5cbe | B7: d4adfbdc606cc51c996bf10182194cf2336d500d0103dc84aee6b79e7a38f365 | C7: 170bc7e29f016cc0648c0b334ae1bb8ce44bf0a73a903e0436a5aebaad8d3b35 | D7: 0446c62360dc6624848a1482d3afbcc2d1febe0eab988cc40c523a39900ff7c9 | J7: 7539259e161ce051c5c4ef7e189a3caa8dffb27150631fdcd3da860451eb28ec | K7: 8b9786921231fd65445cb507afc924aaf234659fa06ed93a604ecd51140d846d | L7: 9937e9c5d030baf3b7189fbc120d5ee0d0a10158f3fc16f94cd2d581ff3e570d
A8: 2569ea19734f486d6f339ae049075023a1eb720c3e9708d9c8f3f22104dfd16b | C8: 530ca979eaf3dafdea222abe36efeaebe6c4c1b01c24698cf1b3250fe27aeb3d | D8: 2b337550dbcc817d4d71433cb2179657d99f90045d1ce0b6bcdac7e38f82faee | J8: 92c2785dee343825573d78e50584f86d85a2c20363708782937e070a8ef1d997 | K8: e9db663c82f6aae3a64ff53d0a11aa5862fac64becaeeea79c6203bffdbc467c | L8: 073981492bea30da3f6af8ffebba5aa066a09e159eba1f932df1f1b1b6d083c6
A9: 311714392906c01c54209ccf96ae4623d8118d01d15de6ee1b2736b066dec0ba | C9: 0894e04cffc1f48c36389b86598785e66f518f48e6c0c7aec111d4a1cd7268d4 | D9: eac61aaced47dc0df93a55391879d64f306c2dee5110221e8952c6ab0ffb78d7 | J9: 78c7d27747e33fdcfbf259946407f5ea91584b5bb4843adf76c263def33e1dea
A10: b1866f3a2577bfb5a5d862563eb31878496f13cdb278a247dd8fe79c92416203 | C10: 1a4c27e6b95c50e2e16b6a084844e17ab0ae7c8ec8d6894eca73d814af6a8964 | D10: 1303679e1b62b14f24307a92a4b4b5ae18267675ceb6ff800493f65648dc0a51 | J10: fec4f3ad5ddca92fab87358738698270d0db052bba03263679136aee919b2faa
A11: 898657aaadd5a4c8a9844d800052b892c56d2a7393bfc8e28d25bf175bcc21f1 | C11: 0e0db477151ef3a4fb2229c95e1142a56738f8ac154f66126f224ff1b1b149a3 | D11: 13759280bce1ad57480272b6020a9a3ae2cfcb8ad3e3e3b45926f14e56716694
A12: 045315e7cd7e64be7fc0722d6ec8898d5d5a10241dc826842c57851d935023c0 | C12: 01605a81d4506734339b73afae35c2a6fa7f50f86d6ed530e21113b792f1189c | D12: 2414ef2cbf32985868868115c78dc6b90f39addfb6a979a605b78bae04617187
A13: 0ac296db1c7565e1e7ff7c94fb5c6d49f3c8f2db7c2b6e024440e2b37738ae3c | C13: 8a850a70f6467fb30fa596d95ee7daf557ea090736e8baf2417c23ecfa91a101 | D13: 6527e7670a887b11966d953ef249e398f899ebd6310683c4026b8279f168db6b
A14: 7c0e2c6dd7fb0ad0107a6a23ff45f4a8f55aaa1b7faef5f92854db1616818eb4 | C14: 18ed7fb6848c0faa59542a8df03b2e03f575b1863c3aa4d2f454541f965b5e72 | D14: 79e5a8321916d4e30adeadbb4a8c90332b3795a745fbc4e2befe772807ce7dd0
A15: f9453a0ab64c5e3ebeb3867feeae21ae253e6616693e953ada6a15e2fe61b9c1 | C15: f943cbd3ebb9525d2b3f66933a9fe465d3a8e438b26cb030799ff60ac3430976
A16: 177466adbfc4aaaf31532a37f424c14645e707fd9513aa392db0fb7f7b767e29 | C16: 1b227d1d30483e766616968a2b38e8d76cb3faeba60505a0c9adb86610a79520
A17: 7c32326e46e2c2f2941e3f8363f0c29ab98073249ef145b84de0ee80ac87d17d | C17: 00c09a0c9701d9ace9e5a0953e162e7145e0e977270223bd4bcec7a6bc018748
A18: ca5a63c31219468374622bbc5c7422bfd79af6a36596b04b395f9b060173ee41 | C18: 6c3134826e8d390b3efb939a51d1596fdce33ab4b79e52b8badedc96f8468538
A19: 7a7b224020654704d1b51974237f1a1b5c486e4c307225355382f041a74b5ebc | C19: 679be341d9ecde9d65235c1630c259d7a61f092b2922c09e42a67640395e2564
A20: 6482e6eae33ffc3a63d3b276f19cad6e166284c984c804e8da8c486f2574b318 | C20: 045d9b1a65c0586ae624eff0f96879318c3b80578bcf35775cf23cc75ad3b857
A21: 3d46975984bb0250f74129f74f9de19e5efa7ba6c0bd4bc2ad47ad1a9762c1c1 | C21: 031d82d0d39544530b54011ec61234f675da9c70f3e68ac49565d6a1f0082f88
A22: 7434bd1842e49452dd90beb7f45086cdae381b8b0b51aeb269faf295ab924e81 | C22: 1be9584f1e10369b10ebce57a24664f21d941fafc3f4fb7d8367d5e4eb78dda9
A23: 27855b8f8516e74087604688230ad6ec9bad115743da75e183b6203c9b69675d | C23: 08695309a074a3d2de63b8347c45d78839720feaad12fd26316786b01aaf448d
A24: 76b5dbb9bee07144c043c208fe4901cb64d6cc9682f3cd1ca544fd302875fcaf | C24: 003864339acfd0219e7704afef2dee303e3151d687ac5b864475955b3bf8ace8
A25: 4665d4c8e4b4236dd3f0dd93fb0318d074414091c02668e2791fb87b50e12ed1 | C25: 71ae0a341f2a218dea0d9600b014d6b104dabf4fc3d39cb2249aff6391662d32
A26: 0b618e33d392e1e60ecdcc1e7183756f08e02add5d0a96e05318c34447b1a258 | C26: 3d75c4529764ad47a2bca21e34eaa3f61e425188ebc602200572cb27e89b489d
... A28: acde855f82379a91cb7f769f1046a5b3fc64691353db5f97e4a4df9f9ef63843 | C28: 679be341d9ecde9d65235c1630c259d7a61f092b2922c09e42a67640395e2564
A29: 9c65b19bb8729d7597e3b3e03ec717f456b3acebeb3df4061c580f740c920652
A30: 38238f8a4dc3f3b670335bd53aafae4d31692b6380533d06306913d1816d9bc4

Sheet 2020.05.06
B1: Additional behaviors | E1: Inconclusive | L1: Discarded
B2: =sum(B4:D4) -> 26 | E2: =sum(E4:K4) -> 9 | L2: =sum(L4:N4) -> 2
A3: No extra activity | B3: Mild additions | C3: Strong additions | D3: Fully evasive | E3: Cmd-line arguments | F3: DynamoRIO bugs | G3: External dependencies | H3: PoC evaders | I3: Interactive | J3: Unable to start program | K3: Undetermined evasions | L3: x64 | M3: Themida | N3: .NET/VB
A4: =COUNTA(A5:A16) -> 12 | B4: =COUNTA(B5:B14) -> 10 | C4: =COUNTA(C5:C12) -> 8 | D4: =COUNTA(D5:D12) -> 8 | E4: =COUNTA(E5) -> 0 | F4: =COUNTA(F5:F6) -> 0 | G4: =COUNTA(G5:G20) -> 1 | H4: =COUNTA(H5) -> 1 | I4: =COUNTA(I5) -> 0 | J4: =COUNTA(J5:J10) -> 6 | K4: =COUNTA(K5:K8) -> 1 | L4: =COUNTA(L5:L8) -> 1 | M4: =COUNTA(M5) -> 1 | N4: =COUNTA(N5) -> 0
A5: 13fb72602eb3ba478c4f596fe815e782b4284e787344a3ffa9f3a64bb546aef9 | B5: 44a1ec18a87ac46cc1b8309860c7f6ddc1529c309ad2e1d0d197448990514860 | C5: e3566acdea5e02b0fe890bae209ad90ea24daa126ba85d00c4fcf0cd71c93ad2 | D5: 069129f03f481727b236fcebd5939aa93eb70142107e9e6d78cb0ae5daabf42f | G5: 2fed24bcaea2fce71c6ef2078695e2baf3475f6ab34fc6ce39814bb9c4ec6655 | H5: d32899762a35a50e73585c038c60fc965dbc78b502785e068f6ffb51cfebd6dd | J5: 4d577f59161bb6b5940660b5686c07e62319c2ea565456c538779fffc19aa337 | K5: be76a2c3e98906400a85f539fb0e88c30c708ecc68ae44002fc8c8a00b3fa44e | L5: e9107764cf266940905ebd196e7ec592ce50b79456280f674160e4e35554682a | M5: 8a74ddd7bfe09e2343325f0bdd5257ef0035663ade9a725403df2a558ebdd9c9
A6: 4997903398a4ae3d9388e0c38e1722af4ed9ca6195ec489560ac6a54aa8e6e15 | B6: 027e5861828c1cdfe220e3917ecaa7072cab703523a19ca162b7f72ba57705f6 | C6: 1c8aaf0db310895a76eba04771d573993d76411539f8ec8d2a194820210d53b4 | D6: 20acbb64fd7a0b18cc1c53c1492c06e8890545c51bca94fa6c756515e79370cb | J6: 5e772368ef1889d25984b6158bc6790dccad9d99a6345c64253e96d3563c2bfc
A7: 1f85a329a94bf5cba68ec7be8cc7fd20b8a7d364f92a19e53a87c7218329e5de | B7: acdc6dad202fd2c425f52c74fb3d03d6454351150cdffea1f7adea20b111c156 | C7: 12ab450f739614e99d79613889fd06185869bee7f7020335fa9cbc75c68a7c47 | D7: 7a8d88e8f5c3bd5410fda5da9fed35ce58e1aa0ab080e1f3b342b11a46c76d35 | J7: 716b59086fedd509fcc69cd16469b07204cfc968000013fda1b7ac88580f9a1d
A8: d3e0c0fd896ce08dcbd0d3be4b8dee13869e9eb70712b98fca96ead35b3bb5f2 | B8: 18dfdebd2e8ad34a10f22279ef809f9fe8e49be5e95309629945d27b09fa29d5 | C8: f22892d4b7ffaeb7eb74eab521b3c5f231a81d3c17490332aa1fe39184c824c9 | D8: 08f5eb2770bb1a971240c77113facbeafbf7bd046740f480878fc0703a240ec4 | J8: 2d153f5e7426754a183c8fb3790ae14147951750d6f99b722814e8e5b487b60b
A9: 0a28e0be1cc26adb3cf3bada9b07f942cd8d56ab66af4f4f32c6f9c7e632e9a6 | B9: 991ae525800296def47e11b55cc1e1f11ffe423c2c8bb0f95dec0f885b405df9 | C9: 6a7478ad98cfa56650d40cb3d488b818c8fd7f060fe432831ab703bcd06278b4 | D9: db0208e64cc8450b19263768d88d6312e425e7decf8c7d771b39566878c4c6fd | J9: aefb19996eb40f5c018c8e351f7c947d26e239474a7666594c83c7db00ba6657
A10: b5290a1a790e25b9302b4ebcf2bbcf441beefb1ad76b5bf09c02fb5f90254619 | B10: b454b9e6bb7c7e98776bde39c4aafcd140e50118b9eaf6b4138cf079eef70322 | C10: 159dde40f6b239233e3e1ce65d1dec43d046f435cf097666496d0e4703a48dbf | D10: 665b1b72ff02156034706a2a4548ac10a338bb350d6f09218b9ce0f53c4d87a8 | J10: 8e926db4448cebd31d44ba55d4a5c7ea92a1773947d017eaa0dd0615efe6837a
A11: 4e10c56f75c1ec75f8eb4975a291bde90c3ee0d1927974d8e709a7d9ea569c34 | B11: 1197db74e965c1244f60c781522e59ca60868727a146ace4953288805610cd5b | C11: d876ee9931787a69037600bd2e628c7636404f019b73064a338f2a160a278783 | D11: d628e621502f044b3b6087b3b041cd4315d3813a56ae566431332efebed30e41 | J11: 24dffbff43869a90e7045ab71145198258dbbdd22e8d74e6f1d2c2b0acebec52
A12: 671b637d4eb8507fd15e33db062c5cbb0afc5a1f48b2cdf7c332a478e300cfb2 | B12: 4b38d607d7a9d57bc94c3391cf7f0bdfb0aa69c57a5226a2708e965856468928 | C12: a9a5ff8b8ba4b09ce959ef85b523d43c5f34b8142acded5fa8a5444756780880 | D12: 429f04f08bd9cb77e7c85d1a0476dbfb0f5a257ed1ca4cefca3f25b47b48efed | J12: 47b37a5ee2c033831e267eda2859ee47a3086d17d3b0074235952f850c8c9b5b
A13: 04817b3318895968747ec994992297179681a584ef4256a18b73688dc7452e6f | B13: 7c4299a0d48dee3e4d10826e45d641890fa518664f2bba15f213a1c860b70425 | J13: 2ad2625a77bce80b44a7a85fb71a6afb674baa54841a9f94266745ef65345d92
A14: b5f260bb692d6c09d126750032045c6ebe5be7345f2029c7c87391005c8a421c | B14: e57400f842ad03cc2300adee1b7980d55a6e73b19680d1870bd737527e3cc96f
A15: 3b264c57509dad989ba4ad472686a26ab6bdee527762c46a291d4bb0d89ba1c0
A16: 43feda13404a6575e6d6222566cb9f3b6a6e5da2c113aa0d272bb82b05ce4a17

Sheet 2020.11.19
B1: Additional behaviors | E1: Inconclusive | L1: Discarded
B2: =sum(B4:D4) -> 25 | E2: =sum(E4:K4) -> 11 | L2: =sum(L4:N4) -> 1
A3: No extra activity | B3: Mild additions | C3: Strong additions | D3: Fully evasive | E3: Cmd-line arguments | F3: DynamoRIO bugs | G3: External dependencies | H3: PoC evaders | I3: Interactive | J3: Unable to start program | K3: Undetermined evasions | L3: x64 | M3: Themida | N3: .NET/VB
A4: =COUNTA(A5:A22) -> 18 | B4: =COUNTA(B5:B13) -> 9 | C4: =COUNTA(C5:C14) -> 10 | D4: =COUNTA(D5:D10) -> 6 | E4: =COUNTA(E5) -> 0 | F4: =COUNTA(F5) -> 0 | G4: =COUNTA(G5:G7) -> 3 | H4: =COUNTA(H5) -> 0 | I4: =COUNTA(I5) -> 1 | J4: =COUNTA(J5) -> 1 | K4: =COUNTA(K5:K10) -> 6 | L4: =COUNTA(L5) -> 1 | M4: =COUNTA(M5) -> 0 | N4: =COUNTA(N5) -> 0
A5: 00a7393b89164e6772d5f66af5ba759aedc8147629b4ea54ae906c57ad3697f9 | B5: 24984e484bf3d221558bb3ad293361ef0fc28145d81033cee922819d42ae0367 | C5: 048e406efcae99c6c805cbd9c041790f153d6836febedb31257e223fcd0438ed | D5: 9422af7bf3cc90ef2adb8d8bb8f745a3bdf0e66cefa5084073dc53ee916d4f80 | G5: 6abfd8dab304707266bb61856ca02c1a7305ee7dbdffd94a97b5077cc24a2ed8 | I5: 4732e590d1c40c6224596c57fac21f820fa03ef0d8e3c5cb6d0bbcf1e0d09443 | J5: 17655970ccadd41c41abbaa50114b1619ac23f8cafde9575082e2b7574ad55a5 | K5: b192ee8aab0eb6d5c72e987628fdc9ae9b22bef1470a6f2bb4443c3000f76813 | L5: 43eba01cdfc2022ce8adff2a141fb3c1f6735427becd6ea4347a64a156602e2f
A6: 236ec5c1e3d9d06b34eca5f453bf2c1cdf91307d219ccd84fff38eaf9da5d417 | B6: 08c41e970d10231c448d1cd1c8b9fa2579c965b62b7c018a17c9b2c5e1da7e4c | C6: d9ff0e06cde23cc7a0865dd66122c339cbc7e31c11d612f0305e0c6267345bc4 | D6: 8bcbef090e0ab2eaafc7aa6045f73038da780bfd794f2b3a34b6dedb2d6419f9 | G6: 5050756c519d5de7cd9bf940daaf55b1afac5419b13c146c5b326989af2744f4 | K6: 0b354d22b98daedf2366f6adc32db461160501af48e2946665046399b19653c0
A7: 0158166468da6df1f5b71455e78554987fb829d431cc126eacb36f1664968d56 | B7: 0bc4818666828a7a9d3157e4a43083011b1a308cb7382ada941c3ed700550a61 | C7: 99f89879e64c329fe577a576d7e681ac2ca470f0b151e549edfc612ce167bdd5 | D7: 05e952699d6dc8fa270f9e49bd9bef006eebe5fb5415f4a7ffe2c64becad890d | G7: 916a6c54e39f4d92bb0901e4812aa82a10e54befe5da2aaa984b3121c5bb7c55 | K7: 1f6ce7158acd93c9c8a58233ede8030573adb661f7ac701c8aaa7f2a3e96c5e1
A8: 0076ad51043e74905312a78c49588384f2d404d4df5859c8b59498703e783b5f | B8: 062d0924d5641e35a020bea1b54528b3aaa043d90a45443902c376b7cd9b4dfd | C8: 829b1f648d24aef58fa77252e13ab6d6a245a2f2358a9ef05963565b91199437 | D8: bfbfdc11a020a8dac0ea646527478d69cc1334d17355da1c0d8d8634ed277bd9 | K8: 22ad67af7e5c35d6e22724db73093bfe208c8c6c737d189039b5ea603ffd87d5
A9: 0b25829d15dc951a44e7652fc6de9d936d7d51f29586d56dbf8fccea419252ac | B9: 622992b7bfdd5f90781545855a3294160930dfc2f1d5b12929122122408d8a98 | C9: 0dcb984799702616f0814f8600fb926ab0b591e8494804852616109cf00f663c | D9: fd957a8e78f2d2a568a46cd2165c151faa2de4d3c832eb3d27b3f2337f30505a | K9: 822634e31bf223b1590a95aeefb6f34234930ecb4fa08720a75547ec85e653e0
A10: 90ed3321c4615ea8a5e379cdedfa932a0e0913d91ebe6a7bf58c7fcab2eba5b7 | B10: 35fc1644707fab4f6eb929ed44d8b207909896b1874ba8c303303e3ef59d6505 | C10: 603a39efa0524a8d3e7ec50ee605971dc21a147cc4bfa632a128c7985846fd53 | D10: 719bc783cde99f77cc89237c19ceeb612bce82ac179d7b600e73b239f907472d | K10: 1e0218853cd923992524f229d6cd4e13ff065f3525189b1e39e348dd52b3f827
A11: 01432c5265f0f46dd666d17da7a5ef43d48ef655e0ba02aed70c65149e76f60b | B11: 1339334fdc798a4dd6de616b23d5e4e91d16ce6e9e219b19f7e4cdaba2395b05 | C11: 51742c01d373dbf850960e4a21dc066ef6cc447cbe3ef6662834fed58cc7f07d
A12: d1fae7bb6ca65930ab068a6ba048706185206c1de2325bb7c0de48f9857633fb | B12: 1d372c91ff95dc9348990815030f403d381f6cc253d0fed44de9a290d8c3bdd6 | C12: 0065ba72c500e687e33fd95c257740a37e6f7838045d0afda2f034542ac85284
A13: 075dba193058150a1070a9e2518bccb5c7377f4633b8b05fa971e6d0da588f29 | B13: 15c18cfb4c97c8a26167de868fcf9f7516e022624e11b87d3de23fc28310d080 | C13: 1bb28f2d43688279e5e2de3ccbd032922cbc3775204aa463cb870a57c3a701e1
A14: 001c35d1b7884a94afdc27539b84a252d7a69e6e876930ec72d02e92b120b922 | C14: 21a890bc19e6ab39aca0cebe2c79f0a2d7c4accd1134b7d6039607a099c0289e
A15: 0a171a622ddb008d0cc264f3ba7d1250a72bfc6f6ba5a27592346d67ef8b153f
A16: 00d9d6da28aa4d6c3372ca8c9636af7455112c93e899d67708ed50d3618986f3
A17: 01543a2cd359b95ce1a96c99094d7f30c33fb9ff5ece8d8114bf1ce2e6a6baae
A18: 07b16d47ce1316e2b10cfe1b4db1a03d3becf52d5329f77a0bcd350a12bd5459
A19: 018cb94936d4a93d02716ca79f0d82eeca8ccb4aecab769a63db5a5573e92c3f
A20: 01036bca1c27175161dfb6f23ab08ffe991892682e028c18ff5fc62de648c0b5
A21: 16aa3c68e1257e3fa19f8df0e4e8adefa082132026bbdbb80765b8dd981f533d
A22: 5882423a17e31eb0e48cddcd735816bfc0b4c18c850d28cfa8cb9890eba53a3d

Sheet 2021.04.15
B1: Additional behaviors | E1: Inconclusive | L1: Discarded
B2: =sum(B4:D4) -> 34 | E2: =sum(E4:K4) -> 20 | L2: =sum(L4:N4) -> 6
A3: No extra activity | B3: Mild additions | C3: Strong additions | D3: Fully evasive | E3: Cmd-line arguments | F3: DynamoRIO bugs | G3: External dependencies | H3: PoC evaders | I3: Interactive | J3: Unable to start program | K3: Undetermined evasions | L3: x64 | M3: Themida | N3: .NET/VB
A4: =COUNTA(A5:A37) -> 33 | B4: =COUNTA(B5:B12) -> 8 | C4: =COUNTA(C5:C19) -> 15 | D4: =COUNTA(D5:D15) -> 11 | E4: =COUNTA(E5) -> 0 | F4: =COUNTA(F5) -> 1 | G4: =COUNTA(G5:G9) -> 5 | H4: =COUNTA(H5) -> 1 | I4: =COUNTA(I5:I10) -> 6 | J4: =COUNTA(J5:J8) -> 4 | K4: =COUNTA(K5:K7) -> 3 | L4: =COUNTA(L5:L10) -> 6 | M4: =COUNTA(M5) -> 0 | N4: =COUNTA(N5) -> 0
A5: 6893df1a02536531e0c6909bd51d37bc6181870f63f48fea0cf6bcf3433c9c16 | B5: 06a5438a471a46fcc2008d2ca0cc19244797bd133f361dd659c5e69bdef50125 | C5: 5a764499fdcd738cea603cb402d3e092e296b3214556d46aea07ad9645450ea0 | D5: b9c705cedc02d6ef6ea1764f6dfb0724ce66c878f5c033d5187b9b877fc926e1 | F5: 303ef69f318596856947e28e1750f220fc3c1932d64d3ec9c64bd0fbc405375f | G5: b5560b9af1a6ada717606b8e8f78813efd3ee48470ae15495c07bcff6ab10c64 | H5: 31444aff3154fb28ade5e86d5a0173d0026ad9b4da100a4174718403e3588687 | I5: c82c6778c988706a26ff487b307c4ccc64745395b852b09b1afcbc0deed33327 | J5: 481ddb0630850075d126a45a656133862d8765b685c8d33addd9e3414467fc2c | K5: bc9027a174a6fdcfb74f25d3c313757b7dd9f8e8e197255a6c28016fd0e93d37 | L5: 9e289ba2389e110183e0e9fbe5af1c6508b41c9589eab4bdd9f2f2d9ee3f7dfc
A6: 2316c2446828a8606031f0a875e3931cf0359308632823e17d831fff48cf65f6 | B6: 11c8c5b983d85c0ecf3d49d31f48026a2d659f2ef097d7655250732f988e79d4 | C6: cebccb9da58bec43204085fe36acfd88ee43c56d529a550a6c3357b5c0dc2ce2 | D6: 68f22901ca321609823c5211354ef8946432d77be3315077b808b5e0fd015562 | G6: d2e8fcc8d5fda016d8459b08e83d7e9d9b5d30c8aa559ec3de6e84d2f25380b8 | I6: 2783d32147b3a7c48fe0532138c4ccd9eabc2b2b77438683df20de0c066302ab | J6: 8020f1233774cc71f54909ebab86957cd64253fc3f72ad1126424d44aba29ebd | K6: e750e4711483a432fb976792a4aec134bb456b3dd63561be8f40ad759cc049fc | L6: 2de5ac3d1746f981d83304bbe493d0832f1beb04b2c815a8fbc72581d4c230dd
A7: 299f39afc4d1556aafe02612d3cb4caa97061426381a2859713e3471d7e042c5 | B7: b0161dad95cb20271062486d07fb2e7a7ddcdd8b7cc955bdbc7d58290bb754fc | C7: 2664c1f511b005babcf113f69945d00a07fee4590b1ddb80c36aa81a69f9ab43 | D7: 2955854aeefb1e81ac15dce570cb0e7299d418b569e64fbce985f2ed131d10e0 | G7: c228aa584dca67d9fd3dc2dfc17d181639cfcadb2692a31119f31fe3b7b0000c | I7: 653dddb96cc98947df999939b36b4226cdbda31b78f4bb2a0c199dcdaed9cec3 | J7: 3430cf6cda4b9b3ded9d7301c12d9907578a0e961c12658a59b5af94c2b15f6e | K7: 662ba8bb0c04af303dbd4e9ceafa55e5d99d30d554f2e9dbedb2eab2c8a62c4b | L7: 4f8deb21569e4b79adfa48a817fc0ea0445db72f5f133b6d686cf6314cfbd3f5
A8: 584454f7d728bfedc059b642c8b92d876736cb3ccbcaea412e153db84494ff3f | B8: 4637d2446db57c4374a39c061d42c30453417da03cf73f9db21abc56e497bfab | C8: 28874ccb360291dfd9a00fcec8643b0024a9d2583a20d536e617cd21ab4e8c28 | D8: 2b81bcbc4e1b8e1c6f7ab1eca090887c0710a73e4fd4179627f2580418d40a4c | G8: c59ad6ab3ff0fe1fcfc22069aa346d90ce9c6325a6bd4ed539da3c18c9f22c1f | I8: 87b23c9985bff53a0e98eab1c20b650770a101fe61ec6f10302959b365fbe977 | J8: 2172271e2eac7cfb94bf5d127eb975870fcdc79b89b3577e98a691609e9123ae | L8: 6173a1953ec65889612d2694f1fe057d96edcb843993e391505ff7751b476dba
A9: 4a4c064f6366ebce23bd146523eda30f253b37d0d2754bb584d76304cec8a8dd | B9: 8b0a9a21d015c1ef095187eafcd3db6a405cb819c0ad40fd7ceb60e50a62ecef | C9: d608b229682e6427f3d58a699d7a642546385c89b2d754cff4a6cc265fc308ae | D9: 55a3c455cfbd70fd91663e251ea65db6452edbb0d730c8e3a48b18a4b3f8df6a | G9: 178664ceb4289df1b3fe709fe46449c80151ffc1eaeb57e151799c5c31e3db2a | I9: 3ec5eea57c2bfe75b9c1b479a02633dfddbdffd13a61ee268e90eaef5d859a4e | L9: 90118fd3688a95b6a0230c2cca087b8906977029d8c581577c89b5c59977fdee
A10: 038e07e1fa7af12989b6c54bedd1e85635f7ff468357489444e0bf26f7b01c0d | B10: 9f8f56fd93f11302a57bc2ff2318bf338e9b7cf6241d6f9d38933478422e0a35 | C10: c4ae52720f806a81f34ce642e02549e48119be115f47f0bdce2621ecdd42d9ff | D10: b715e12e64e2883eaf51f8925cc7c40a2444080f3fd481d6969ef5d4b16dbe56 | I10: 587dccf1a48870bc606df2dd3da2183f6c2037d604a1762fb6196ff983fd32e2 | L10: 4439725e0507aeefee1809845d4ea32d02192cca440db216adc48f6e6d04343f
A11: 040bf218992d20814c40079d1224395104e947b855e258853b6846166d54f9f4 | B11: faa86b3e86bbc63a0a119132008e3e316ee658569c8ce19079e536656cdd9ee8 | C11: 112b75cb92cf7f6ff49ea71ce5c336ba85511b787ff081f34bde8e9a976ef50f | D11: 21fc6ae8f7c0619af4c03ce300bb271f3d3ec43cd196bb04250839dd9700ecad
A12: 4a9a372e30b8f4828d23f00b046d8fbaf2280f33363e8a2e430862f6f4e8398b | B12: 6b0657bd65e4ad6d847b2a6fb8abe7d7dba4736dac9cd4f51894d8e0b9f1e0a3 | C12: adbb5a209c45518319951006f0121fb05bf7faed00df07b229b3e523e6ffb0d0 | D12: 4149f025cfce38098d9b8a048c169651a38d312ed6e026b59f034252bdbca5e6
A13: 3b6d9879e88bb064e891f09c4522163b34114d11ba07cdca8d8919440b37dde4 | C13: d99884fcba888ea19d88580baaab6bdd4dc42205f5135b8df3dda59d13ab3382 | D13: 5410e42dc85547581cf8322611834df8d85df7e79b014ba035d98fbe803e05fd
A14: 0c008dc898a86d077547b0d2738c3a5c19149b5a2353d8196f459942c426260b | C14: 45407002fe73ca5ed30c2a7932fd4577ade2e7e57a28699fbe173827cdc47d65 | D14: b6c676c3d6548e10b623a3c3cb3d5593da03c1d4b0945d44aad0ccc9369dc267
A15: 00c8d6ee5f434cd956febb0061b070c37c13162d934db13f702b3be51bce9c73 | C15: 511eb18395f6ac79454375a125aa05ff929a3e96839977b185e164909a6969f1 | D15: a8d4e0b7cb1ccaae5fd19da1765e2c35b74671b8420f0006f8fd26343622813e
A16: 50c96ef81128a1515b362c7f888a3ead4364abb427a5151337baac1fed84354f | C16: ed776958231043c5d7c167c943ce7f2e21a9acafd5943de53a6b326386c8ed47
A17: 07efe912a8206493ec273a4fb5933fcb1f9f5972dd0c4aec2bc4bf4ed6c0f07d | C17: 6cc01f6bcb55609da322589ca0311459258248d04e463a49b275719c35737eb4
A18: 0c0f8e866c727b7fbc92c078361ed645cd70c4b78d9860e1d3d18065afd72d42 | C18: 3f9fa81a421324836fb501e8b43dce8ca7c66bc0727b20c6c2b32840f5ea0905
A19: 075da2c953ae8a4992d3c208fb2b7f07ff60c0e9e2cc9c26c62c1a6249f40d7a | C19: 2676abe42448151789f021bcc00bb438dbf59846084d530f0344313a0154bfb5
A20: f454622ad2ea0179431365de97aa74a5968e9d100952e6e75e0a90850aa0091a
A21: f90715b20c04379fe424569d6fe6278363cbd25a4db5d9cdf31c2ebc65e7c924
A22: 009adbd6cc1d75432109140e381d927b4ebcecb529f090ef543af5c11ccb0d0b
A23: 183fe9ff038ac63ef3adb8f28e39366fd32f918d74729565236e97a12b9df0e8
A24: c3458542e371765273b80c96b4a453fefdf91099851a6a8b7faa96f0a15e18d9
A25: 062c399b400bf2df3ed28e45969b216ea2e5cb9cf40e1b62b5a94d2fa97f0117
A26: 23d354fb17846ad08106e3d5a8ae9d7fdd73a38904fda002b054cf0ca0719f3b
A27: bde0b03bb7a4a38770534ccd2515d9f5a3fff204f1a6228f54491fb5547639b9
A28: 02eade9c2cadb965b92355b4992dd77a33f1501d7a03b1796836b2aa8326c974
A29: 2d600f88dbc3905828cac5a6d18daef8c732c14e877c752dd45374dcd8905469
A30: 01dfbb42630eecaea64609e21639915685fe46ab7380d773a0d006110419c63b
A31: 3625aaaecaaf27bb30f726d2780fcccd3713bfc697489a4ab88b2ea7c8cf8d65
... A37: 3c4926dadc29e97b2f65005849ebe07028b57cafc1c424c815c20246d52d300f

Sheet 2021.11.03
B1: Additional behaviors | E1: Inconclusive | L1: Discarded
B2: =sum(B4:D4) -> 55 | E2: =sum(E4:K4) -> 22 | L2: =sum(L4:N4) -> 21
A3: No extra activity | B3: Mild additions | C3: Strong additions | D3: Fully evasive | E3: Cmd-line arguments | F3: DynamoRIO bugs | G3: External dependencies | H3: PoC evaders | I3: Interactive | J3: Unable to start program | K3: Undetermined evasions | L3: x64 | M3: Themida | N3: .NET/VB
A4: =COUNTA(A5:A53) -> 49 | B4: =COUNTA(B5:B17) -> 13 | C4: =COUNTA(C5:C38) -> 34 | D4: =COUNTA(D5:D12) -> 8 | E4: =COUNTA(E5:E6) -> 2 | F4: =COUNTA(F5:F9) -> 5 | G4: =COUNTA(G5:G9) -> 5 | H4: =COUNTA(H5) -> 1 | I4: =COUNTA(I5:I6) -> 2 | J4: =COUNTA(J5:J9) -> 5 | K4: =COUNTA(K5:K6) -> 2 | L4: =COUNTA(L5:L21) -> 17 | M4: =COUNTA(M5) -> 1 | N4: =COUNTA(N5:N7) -> 3
A5: 0e9dd399634b8442c2fd8b5e9c5606227d6e1e7332f1bbeddaddcdb4372b629f | B5: 5b5d763e077e2c2d4076d9b76f9a6b47231fa7478eaefdbe3f05102d0bd9149b | C5: 39ef49b7f087658f267e5bbe3ff1d6352848996e246b0d972b506dd95a8123bb | D5: 9c4867b0ce01aa231f2e985d72fdf1d3729a1eac9c90ff6cd2e85a0614a25193 | E5: 1011d2d71a07b052fc534be696525cd8a02ad3ef30d4cd60f17743121dd93287 | F5: 98fc26728c6573dd1963e7cb23fb750e433e1426d5d48506249660204b380d53 | G5: 25d3425dd81e7b5800638909b7b3ceb08d96ed968a15324b4e0c5aa4e55c6cd6 | H5: 6e90d4868823da80bc9cca252ac6dd548131b07a81464c5d85b32f356254531d | I5: 246012b9510167382741216f31e2c6ec3fedcaac7e71c2e590f18c0cb7ecc653 | J5: 0c1e9f3a80421c1346cf958beaea63a0f4fe3961a53c77cd511768dd4c67fc7c | K5: 001d2ed4c48899a87f02a7c1876c8aaca13f91a2ca71a3a74e1cc351aacad119 | L5: 8c53712978b18ad365307114fd0e5faa4471822e8baf06f501c84bc93e1abb2b | M5: 5886eb94c1ecacd377153ec939cece90c52f9842523670eae55ba18ca58a4095 | N5: 5034bd6fcc8b31083fdeae6624e4d69c92a610fecbee2335f8d8638924dc64fe
A6: 06882231714592010e52fdb9a92754f932cc8abeb47b81fa23b08dee9b2e38aa | B6: 03a41a911019b049f452c1c9f4e115f7729905279d6634db9b065c89caed11d0 | C6: 0380b032e7bdd9d8c68fea4634d76fc109e7b4c8306ee922f379a58f12a1445b | D6: f28442764ad147c119c2227c8906b4c2759d55a6470818051100ef112946b9af | E6: 1953fb7984865bd6ece8c7a22aa67f8e7846b3190c35401574488d50b79c9620 | F6: 726b8d024f8eb4f69ac824a9275babb6e33f0ee3e1272b99f50cf5a4303fc5ad | G6: 92a21df4ff5fdbe9758e649a38f8c3f994b3d4ed79d249db4df2028dbace95a8 | I6: a5a18cb781620ad5979882cce99d9d6a7c01f5dbfb1da1996799c70ed6b0c5d5 | J6: e4de39cbe3897ce8f18f91e46e4fbb041c5c6e0503c99a899d483c97d7dcf31d | K6: 65957dc5e63769658761935693ba2779d13a3fe1bb51c318ad7933bc8ff650a9 | L6: 16776e233bbd4a7632fd7551c4c92e047edaf57ba0d49eff0ea4fc5c209930f7 | N6: 66f83be0871a9846f6f41df9871f267fa744696fe451018947cd9701088e4e16
